Workbook

Sheet 읽어주세요
A1: CUFIC WTS 게임 데이터셋 제작 양식 (v4)
A3: 이 파일의 시트 5개를 채우면 게임 한 판이 완성됩니다.
A4: 노란 칸 = 꼭 채우는 곳 / 파란 칸 = 선택 (비워도 됨, 헤더에 "(선택)" 표시)
A5: 지금 들어있는 내용은 "기본 데이터셋 (2025)" 예시입니다 — 지우지 말고 고쳐 쓰는 걸 추천해요.
A6: 종목·힌트 개수는 자유입니다. 행을 추가/삭제하면 그대로 게임 구성이 돼요. (힌트는 라운드당 등급별 1개 이상 권장)
A8: ★ 가격은 두 가지 방법으로 쓸 수 있어요
A9: · 그냥 숫자 = 가격(원) (예: 7300)
A10: · %를 붙이면 = 전년 대비 등락률 → 업로드할 때 자동으로 가격으로 계산돼요 (예: +80%, -25%)
A11: · 단, 종목이 처음 등장하는 연도는 반드시 가격(숫자)으로! (기준점이 필요해요)
A12: · 섞어 써도 됩니다: 2020=7300, 2021=+80%, 2022=17700 처럼
A14: 작성 순서 (이 순서대로!)
A15: ① 게임설정 — 라운드 수·연도·시드 확정
... A34: ④ 이 양식은 5라운드 + 최종연도(총 6개 연도) 기준입니다. 연도 값은 게임설정에서 바꾸면 전 시트에 따라옵니다.

Sheet 게임설정
A1: ① 게임설정
A2: 항목 이름(A열)은 바꾸지 말고 값(B열)만 수정하세요. 라운드 연도는 ②종목 시트의 가격 열과 일치해야 해요.
A4: 항목 | B4: 값 | C4: 설명
A5: 총 라운드 수 | B5: 5 | C5: 보통 5
A6: 시작 시드머니(원) | B6: 100000000 | C6: 전 조 동일
A7: 타이머(초) | B7: 600 | C7: 600 = 10분
A8: 최종 정산 연도 | B8: 2025 | C8: 대회 종료 시 이 연도 가격으로 최종 평가
A9: R1 연도 | B9: 2020 | C9: 1라운드에서 거래하는 연도
A10: R2 연도 | B10: 2021 | C10: 2라운드에서 거래하는 연도
A11: R3 연도 | B11: 2022 | C11: 3라운드에서 거래하는 연도
A12: R4 연도 | B12: 2023 | C12: 4라운드에서 거래하는 연도
A13: R5 연도 | B13: 2024 | C13: 5라운드에서 거래하는 연도

Sheet 종목
A1: ② 종목과 연도별 가격
A2: 한 행 = 종목 하나. ID는 S01, S02… 순서로. 가격 칸: 숫자=가격(원), %붙이면=전년 대비 등락률(예: +80%). 첫 등장 연도는 반드시 가격! 빈칸/0 = 거래정지·미상장. 행 추가/삭제 자유.
A4: ID | B4: 종목명 | C4: 한 줄 소개 | D4: 업종 (선택) | E4: 상장라운드 | F4: =게임설정!$B$9&"년 가격" -> 2020년 가격 | G4: =게임설정!$B$10&"년 가격" -> 2021년 가격 | H4: =게임설정!$B$11&"년 가격" -> 2022년 가격 | I4: =게임설정!$B$12&"년 가격" -> 2023년 가격 | J4: =게임설정!$B$13&"년 가격" -> 2024년 가격 | K4: =게임설정!$B$8&"년 가격" -> 2025년 가격

Sheet 재무제표
A1: ③ 재무제표 (종목 × 연도) — 자동 연결
A2: ID·종목명·연도는 종목 시트에서 자동으로 채워집니다(회색). 여러분은 크림색 입력 7칸(억원)만 채우세요. 미상장·폐지 연도는 빈 칸으로 두면 됩니다. ★종목 목록을 먼저 확정한 뒤 채우세요.
A4: 종목ID | B4: 종목명 | C4: 연도 | D4: 유동자산(억) | E4: 비유동자산(억) | F4: 유동부채(억) | G4: 비유동부채(억) | H4: 매출(억) | I4: 영업비용(억) | J4: 영업외비용(억) | K4: 자산합계 ※자동 | L4: 부채합계 ※자동 | M4: 자본 ※자동 | N4: 영업이익 ※자동 | O4: 당기순이익 ※자동 | P4: 부채비율(%) ※자동 | Q4: ROE(%) ※자동
A5: =IF(종목!A5="","",종목!A5) | B5: =IF(종목!A5="","",종목!B5) | C5: =IF(종목!A5="","",게임설정!$B$9) | K5: =IF(D5="","",D5+E5) | L5: =IF(F5="","",F5+G5) | M5: =IF(K5="","",K5-L5) | N5: =IF(H5="","",H5-I5) | O5: =IF(N5="","",N5-J5) | P5: =IF(OR(M5="",M5<=0),"자본잠식",ROUND(L5/M5*100,1)) | Q5: =IF(OR(M5="",M5<=0),"—",ROUND(O5/M5*100,1))
A6: =IF(종목!A5="","",종목!A5) | B6: =IF(종목!A5="","",종목!B5) | C6: =IF(종목!A5="","",게임설정!$B$10) | K6: =IF(D6="","",D6+E6) | L6: =IF(F6="","",F6+G6) | M6: =IF(K6="","",K6-L6) | N6: =IF(H6="","",H6-I6) | O6: =IF(N6="","",N6-J6) | P6: =IF(OR(M6="",M6<=0),"자본잠식",ROUND(L6/M6*100,1)) | Q6: =IF(OR(M6="",M6<=0),"—",ROUND(O6/M6*100,1))
A7: =IF(종목!A5="","",종목!A5) | B7: =IF(종목!A5="","",종목!B5) | C7: =IF(종목!A5="","",게임설정!$B$11) | K7: =IF(D7="","",D7+E7) | L7: =IF(F7="","",F7+G7) | M7: =IF(K7="","",K7-L7) | N7: =IF(H7="","",H7-I7) | O7: =IF(N7="","",N7-J7) | P7: =IF(OR(M7="",M7<=0),"자본잠식",ROUND(L7/M7*100,1)) | Q7: =IF(OR(M7="",M7<=0),"—",ROUND(O7/M7*100,1))
A8: =IF(종목!A5="","",종목!A5) | B8: =IF(종목!A5="","",종목!B5) | C8: =IF(종목!A5="","",게임설정!$B$12) | K8: =IF(D8="","",D8+E8) | L8: =IF(F8="","",F8+G8) | M8: =IF(K8="","",K8-L8) | N8: =IF(H8="","",H8-I8) | O8: =IF(N8="","",N8-J8) | P8: =IF(OR(M8="",M8<=0),"자본잠식",ROUND(L8/M8*100,1)) | Q8: =IF(OR(M8="",M8<=0),"—",ROUND(O8/M8*100,1))
A9: =IF(종목!A5="","",종목!A5) | B9: =IF(종목!A5="","",종목!B5) | C9: =IF(종목!A5="","",게임설정!$B$13) | K9: =IF(D9="","",D9+E9) | L9: =IF(F9="","",F9+G9) | M9: =IF(K9="","",K9-L9) | N9: =IF(H9="","",H9-I9) | O9: =IF(N9="","",N9-J9) | P9: =IF(OR(M9="",M9<=0),"자본잠식",ROUND(L9/M9*100,1)) | Q9: =IF(OR(M9="",M9<=0),"—",ROUND(O9/M9*100,1))
A10: =IF(종목!A5="","",종목!A5) | B10: =IF(종목!A5="","",종목!B5) | C10: =IF(종목!A5="","",게임설정!$B$8) | K10: =IF(D10="","",D10+E10) | L10: =IF(F10="","",F10+G10) | M10: =IF(K10="","",K10-L10) | N10: =IF(H10="","",H10-I10) | O10: =IF(N10="","",N10-J10) | P10: =IF(OR(M10="",M10<=0),"자본잠식",ROUND(L10/M10*100,1)) | Q10: =IF(OR(M10="",M10<=0),"—",ROUND(O10/M10*100,1))
A11: =IF(종목!A6="","",종목!A6) | B11: =IF(종목!A6="","",종목!B6) | C11: =IF(종목!A6="","",게임설정!$B$9) | K11: =IF(D11="","",D11+E11) | L11: =IF(F11="","",F11+G11) | M11: =IF(K11="","",K11-L11) | N11: =IF(H11="","",H11-I11) | O11: =IF(N11="","",N11-J11) | P11: =IF(OR(M11="",M11<=0),"자본잠식",ROUND(L11/M11*100,1)) | Q11: =IF(OR(M11="",M11<=0),"—",ROUND(O11/M11*100,1))
A12: =IF(종목!A6="","",종목!A6) | B12: =IF(종목!A6="","",종목!B6) | C12: =IF(종목!A6="","",게임설정!$B$10) | K12: =IF(D12="","",D12+E12) | L12: =IF(F12="","",F12+G12) | M12: =IF(K12="","",K12-L12) | N12: =IF(H12="","",H12-I12) | O12: =IF(N12="","",N12-J12) | P12: =IF(OR(M12="",M12<=0),"자본잠식",ROUND(L12/M12*100,1)) | Q12: =IF(OR(M12="",M12<=0),"—",ROUND(O12/M12*100,1))
A13: =IF(종목!A6="","",종목!A6) | B13: =IF(종목!A6="","",종목!B6) | C13: =IF(종목!A6="","",게임설정!$B$11) | K13: =IF(D13="","",D13+E13) | L13: =IF(F13="","",F13+G13) | M13: =IF(K13="","",K13-L13) | N13: =IF(H13="","",H13-I13) | O13: =IF(N13="","",N13-J13) | P13: =IF(OR(M13="",M13<=0),"자본잠식",ROUND(L13/M13*100,1)) | Q13: =IF(OR(M13="",M13<=0),"—",ROUND(O13/M13*100,1))
A14: =IF(종목!A6="","",종목!A6) | B14: =IF(종목!A6="","",종목!B6) | C14: =IF(종목!A6="","",게임설정!$B$12) | K14: =IF(D14="","",D14+E14) | L14: =IF(F14="","",F14+G14) | M14: =IF(K14="","",K14-L14) | N14: =IF(H14="","",H14-I14) | O14: =IF(N14="","",N14-J14) | P14: =IF(OR(M14="",M14<=0),"자본잠식",ROUND(L14/M14*100,1)) | Q14: =IF(OR(M14="",M14<=0),"—",ROUND(O14/M14*100,1))
A15: =IF(종목!A6="","",종목!A6) | B15: =IF(종목!A6="","",종목!B6) | C15: =IF(종목!A6="","",게임설정!$B$13) | K15: =IF(D15="","",D15+E15) | L15: =IF(F15="","",F15+G15) | M15: =IF(K15="","",K15-L15) | N15: =IF(H15="","",H15-I15) | O15: =IF(N15="","",N15-J15) | P15: =IF(OR(M15="",M15<=0),"자본잠식",ROUND(L15/M15*100,1)) | Q15: =IF(OR(M15="",M15<=0),"—",ROUND(O15/M15*100,1))
A16: =IF(종목!A6="","",종목!A6) | B16: =IF(종목!A6="","",종목!B6) | C16: =IF(종목!A6="","",게임설정!$B$8) | K16: =IF(D16="","",D16+E16) | L16: =IF(F16="","",F16+G16) | M16: =IF(K16="","",K16-L16) | N16: =IF(H16="","",H16-I16) | O16: =IF(N16="","",N16-J16) | P16: =IF(OR(M16="",M16<=0),"자본잠식",ROUND(L16/M16*100,1)) | Q16: =IF(OR(M16="",M16<=0),"—",ROUND(O16/M16*100,1))
A17: =IF(종목!A7="","",종목!A7) | B17: =IF(종목!A7="","",종목!B7) | C17: =IF(종목!A7="","",게임설정!$B$9) | K17: =IF(D17="","",D17+E17) | L17: =IF(F17="","",F17+G17) | M17: =IF(K17="","",K17-L17) | N17: =IF(H17="","",H17-I17) | O17: =IF(N17="","",N17-J17) | P17: =IF(OR(M17="",M17<=0),"자본잠식",ROUND(L17/M17*100,1)) | Q17: =IF(OR(M17="",M17<=0),"—",ROUND(O17/M17*100,1))
A18: =IF(종목!A7="","",종목!A7) | B18: =IF(종목!A7="","",종목!B7) | C18: =IF(종목!A7="","",게임설정!$B$10) | K18: =IF(D18="","",D18+E18) | L18: =IF(F18="","",F18+G18) | M18: =IF(K18="","",K18-L18) | N18: =IF(H18="","",H18-I18) | O18: =IF(N18="","",N18-J18) | P18: =IF(OR(M18="",M18<=0),"자본잠식",ROUND(L18/M18*100,1)) | Q18: =IF(OR(M18="",M18<=0),"—",ROUND(O18/M18*100,1))
A19: =IF(종목!A7="","",종목!A7) | B19: =IF(종목!A7="","",종목!B7) | C19: =IF(종목!A7="","",게임설정!$B$11) | K19: =IF(D19="","",D19+E19) | L19: =IF(F19="","",F19+G19) | M19: =IF(K19="","",K19-L19) | N19: =IF(H19="","",H19-I19) | O19: =IF(N19="","",N19-J19) | P19: =IF(OR(M19="",M19<=0),"자본잠식",ROUND(L19/M19*100,1)) | Q19: =IF(OR(M19="",M19<=0),"—",ROUND(O19/M19*100,1))
A20: =IF(종목!A7="","",종목!A7) | B20: =IF(종목!A7="","",종목!B7) | C20: =IF(종목!A7="","",게임설정!$B$12) | K20: =IF(D20="","",D20+E20) | L20: =IF(F20="","",F20+G20) | M20: =IF(K20="","",K20-L20) | N20: =IF(H20="","",H20-I20) | O20: =IF(N20="","",N20-J20) | P20: =IF(OR(M20="",M20<=0),"자본잠식",ROUND(L20/M20*100,1)) | Q20: =IF(OR(M20="",M20<=0),"—",ROUND(O20/M20*100,1))
A21: =IF(종목!A7="","",종목!A7) | B21: =IF(종목!A7="","",종목!B7) | C21: =IF(종목!A7="","",게임설정!$B$13) | K21: =IF(D21="","",D21+E21) | L21: =IF(F21="","",F21+G21) | M21: =IF(K21="","",K21-L21) | N21: =IF(H21="","",H21-I21) | O21: =IF(N21="","",N21-J21) | P21: =IF(OR(M21="",M21<=0),"자본잠식",ROUND(L21/M21*100,1)) | Q21: =IF(OR(M21="",M21<=0),"—",ROUND(O21/M21*100,1))
A22: =IF(종목!A7="","",종목!A7) | B22: =IF(종목!A7="","",종목!B7) | C22: =IF(종목!A7="","",게임설정!$B$8) | K22: =IF(D22="","",D22+E22) | L22: =IF(F22="","",F22+G22) | M22: =IF(K22="","",K22-L22) | N22: =IF(H22="","",H22-I22) | O22: =IF(N22="","",N22-J22) | P22: =IF(OR(M22="",M22<=0),"자본잠식",ROUND(L22/M22*100,1)) | Q22: =IF(OR(M22="",M22<=0),"—",ROUND(O22/M22*100,1))
A23: =IF(종목!A8="","",종목!A8) | B23: =IF(종목!A8="","",종목!B8) | C23: =IF(종목!A8="","",게임설정!$B$9) | K23: =IF(D23="","",D23+E23) | L23: =IF(F23="","",F23+G23) | M23: =IF(K23="","",K23-L23) | N23: =IF(H23="","",H23-I23) | O23: =IF(N23="","",N23-J23) | P23: =IF(OR(M23="",M23<=0),"자본잠식",ROUND(L23/M23*100,1)) | Q23: =IF(OR(M23="",M23<=0),"—",ROUND(O23/M23*100,1))
A24: =IF(종목!A8="","",종목!A8) | B24: =IF(종목!A8="","",종목!B8) | C24: =IF(종목!A8="","",게임설정!$B$10) | K24: =IF(D24="","",D24+E24) | L24: =IF(F24="","",F24+G24) | M24: =IF(K24="","",K24-L24) | N24: =IF(H24="","",H24-I24) | O24: =IF(N24="","",N24-J24) | P24: =IF(OR(M24="",M24<=0),"자본잠식",ROUND(L24/M24*100,1)) | Q24: =IF(OR(M24="",M24<=0),"—",ROUND(O24/M24*100,1))
A25: =IF(종목!A8="","",종목!A8) | B25: =IF(종목!A8="","",종목!B8) | C25: =IF(종목!A8="","",게임설정!$B$11) | K25: =IF(D25="","",D25+E25) | L25: =IF(F25="","",F25+G25) | M25: =IF(K25="","",K25-L25) | N25: =IF(H25="","",H25-I25) | O25: =IF(N25="","",N25-J25) | P25: =IF(OR(M25="",M25<=0),"자본잠식",ROUND(L25/M25*100,1)) | Q25: =IF(OR(M25="",M25<=0),"—",ROUND(O25/M25*100,1))
A26: =IF(종목!A8="","",종목!A8) | B26: =IF(종목!A8="","",종목!B8) | C26: =IF(종목!A8="","",게임설정!$B$12) | K26: =IF(D26="","",D26+E26) | L26: =IF(F26="","",F26+G26) | M26: =IF(K26="","",K26-L26) | N26: =IF(H26="","",H26-I26) | O26: =IF(N26="","",N26-J26) | P26: =IF(OR(M26="",M26<=0),"자본잠식",ROUND(L26/M26*100,1)) | Q26: =IF(OR(M26="",M26<=0),"—",ROUND(O26/M26*100,1))
A27: =IF(종목!A8="","",종목!A8) | B27: =IF(종목!A8="","",종목!B8) | C27: =IF(종목!A8="","",게임설정!$B$13) | K27: =IF(D27="","",D27+E27) | L27: =IF(F27="","",F27+G27) | M27: =IF(K27="","",K27-L27) | N27: =IF(H27="","",H27-I27) | O27: =IF(N27="","",N27-J27) | P27: =IF(OR(M27="",M27<=0),"자본잠식",ROUND(L27/M27*100,1)) | Q27: =IF(OR(M27="",M27<=0),"—",ROUND(O27/M27*100,1))
A28: =IF(종목!A8="","",종목!A8) | B28: =IF(종목!A8="","",종목!B8) | C28: =IF(종목!A8="","",게임설정!$B$8) | K28: =IF(D28="","",D28+E28) | L28: =IF(F28="","",F28+G28) | M28: =IF(K28="","",K28-L28) | N28: =IF(H28="","",H28-I28) | O28: =IF(N28="","",N28-J28) | P28: =IF(OR(M28="",M28<=0),"자본잠식",ROUND(L28/M28*100,1)) | Q28: =IF(OR(M28="",M28<=0),"—",ROUND(O28/M28*100,1))
A29: =IF(종목!A9="","",종목!A9) | B29: =IF(종목!A9="","",종목!B9) | C29: =IF(종목!A9="","",게임설정!$B$9) | K29: =IF(D29="","",D29+E29) | L29: =IF(F29="","",F29+G29) | M29: =IF(K29="","",K29-L29) | N29: =IF(H29="","",H29-I29) | O29: =IF(N29="","",N29-J29) | P29: =IF(OR(M29="",M29<=0),"자본잠식",ROUND(L29/M29*100,1)) | Q29: =IF(OR(M29="",M29<=0),"—",ROUND(O29/M29*100,1))
A30: =IF(종목!A9="","",종목!A9) | B30: =IF(종목!A9="","",종목!B9) | C30: =IF(종목!A9="","",게임설정!$B$10) | K30: =IF(D30="","",D30+E30) | L30: =IF(F30="","",F30+G30) | M30: =IF(K30="","",K30-L30) | N30: =IF(H30="","",H30-I30) | O30: =IF(N30="","",N30-J30) | P30: =IF(OR(M30="",M30<=0),"자본잠식",ROUND(L30/M30*100,1)) | Q30: =IF(OR(M30="",M30<=0),"—",ROUND(O30/M30*100,1))
A31: =IF(종목!A9="","",종목!A9) | B31: =IF(종목!A9="","",종목!B9) | C31: =IF(종목!A9="","",게임설정!$B$11) | K31: =IF(D31="","",D31+E31) | L31: =IF(F31="","",F31+G31) | M31: =IF(K31="","",K31-L31) | N31: =IF(H31="","",H31-I31) | O31: =IF(N31="","",N31-J31) | P31: =IF(OR(M31="",M31<=0),"자본잠식",ROUND(L31/M31*100,1)) | Q31: =IF(OR(M31="",M31<=0),"—",ROUND(O31/M31*100,1))
A32: =IF(종목!A9="","",종목!A9) | B32: =IF(종목!A9="","",종목!B9) | C32: =IF(종목!A9="","",게임설정!$B$12) | K32: =IF(D32="","",D32+E32) | L32: =IF(F32="","",F32+G32) | M32: =IF(K32="","",K32-L32) | N32: =IF(H32="","",H32-I32) | O32: =IF(N32="","",N32-J32) | P32: =IF(OR(M32="",M32<=0),"자본잠식",ROUND(L32/M32*100,1)) | Q32: =IF(OR(M32="",M32<=0),"—",ROUND(O32/M32*100,1))
A33: =IF(종목!A9="","",종목!A9) | B33: =IF(종목!A9="","",종목!B9) | C33: =IF(종목!A9="","",게임설정!$B$13) | K33: =IF(D33="","",D33+E33) | L33: =IF(F33="","",F33+G33) | M33: =IF(K33="","",K33-L33) | N33: =IF(H33="","",H33-I33) | O33: =IF(N33="","",N33-J33) | P33: =IF(OR(M33="",M33<=0),"자본잠식",ROUND(L33/M33*100,1)) | Q33: =IF(OR(M33="",M33<=0),"—",ROUND(O33/M33*100,1))
A34: =IF(종목!A9="","",종목!A9) | B34: =IF(종목!A9="","",종목!B9) | C34: =IF(종목!A9="","",게임설정!$B$8) | K34: =IF(D34="","",D34+E34) | L34: =IF(F34="","",F34+G34) | M34: =IF(K34="","",K34-L34) | N34: =IF(H34="","",H34-I34) | O34: =IF(N34="","",N34-J34) | P34: =IF(OR(M34="",M34<=0),"자본잠식",ROUND(L34/M34*100,1)) | Q34: =IF(OR(M34="",M34<=0),"—",ROUND(O34/M34*100,1))
A35: =IF(종목!A10="","",종목!A10) | B35: =IF(종목!A10="","",종목!B10) | C35: =IF(종목!A10="","",게임설정!$B$9) | K35: =IF(D35="","",D35+E35) | L35: =IF(F35="","",F35+G35) | M35: =IF(K35="","",K35-L35) | N35: =IF(H35="","",H35-I35) | O35: =IF(N35="","",N35-J35) | P35: =IF(OR(M35="",M35<=0),"자본잠식",ROUND(L35/M35*100,1)) | Q35: =IF(OR(M35="",M35<=0),"—",ROUND(O35/M35*100,1))
A36: =IF(종목!A10="","",종목!A10) | B36: =IF(종목!A10="","",종목!B10) | C36: =IF(종목!A10="","",게임설정!$B$10) | K36: =IF(D36="","",D36+E36) | L36: =IF(F36="","",F36+G36) | M36: =IF(K36="","",K36-L36) | N36: =IF(H36="","",H36-I36) | O36: =IF(N36="","",N36-J36) | P36: =IF(OR(M36="",M36<=0),"자본잠식",ROUND(L36/M36*100,1)) | Q36: =IF(OR(M36="",M36<=0),"—",ROUND(O36/M36*100,1))
A37: =IF(종목!A10="","",종목!A10) | B37: =IF(종목!A10="","",종목!B10) | C37: =IF(종목!A10="","",게임설정!$B$11) | K37: =IF(D37="","",D37+E37) | L37: =IF(F37="","",F37+G37) | M37: =IF(K37="","",K37-L37) | N37: =IF(H37="","",H37-I37) | O37: =IF(N37="","",N37-J37) | P37: =IF(OR(M37="",M37<=0),"자본잠식",ROUND(L37/M37*100,1)) | Q37: =IF(OR(M37="",M37<=0),"—",ROUND(O37/M37*100,1))
A38: =IF(종목!A10="","",종목!A10) | B38: =IF(종목!A10="","",종목!B10) | C38: =IF(종목!A10="","",게임설정!$B$12) | K38: =IF(D38="","",D38+E38) | L38: =IF(F38="","",F38+G38) | M38: =IF(K38="","",K38-L38) | N38: =IF(H38="","",H38-I38) | O38: =IF(N38="","",N38-J38) | P38: =IF(OR(M38="",M38<=0),"자본잠식",ROUND(L38/M38*100,1)) | Q38: =IF(OR(M38="",M38<=0),"—",ROUND(O38/M38*100,1))
A39: =IF(종목!A10="","",종목!A10) | B39: =IF(종목!A10="","",종목!B10) | C39: =IF(종목!A10="","",게임설정!$B$13) | K39: =IF(D39="","",D39+E39) | L39: =IF(F39="","",F39+G39) | M39: =IF(K39="","",K39-L39) | N39: =IF(H39="","",H39-I39) | O39: =IF(N39="","",N39-J39) | P39: =IF(OR(M39="",M39<=0),"자본잠식",ROUND(L39/M39*100,1)) | Q39: =IF(OR(M39="",M39<=0),"—",ROUND(O39/M39*100,1))
A40: =IF(종목!A10="","",종목!A10) | B40: =IF(종목!A10="","",종목!B10) | C40: =IF(종목!A10="","",게임설정!$B$8) | K40: =IF(D40="","",D40+E40) | L40: =IF(F40="","",F40+G40) | M40: =IF(K40="","",K40-L40) | N40: =IF(H40="","",H40-I40) | O40: =IF(N40="","",N40-J40) | P40: =IF(OR(M40="",M40<=0),"자본잠식",ROUND(L40/M40*100,1)) | Q40: =IF(OR(M40="",M40<=0),"—",ROUND(O40/M40*100,1))
A41: =IF(종목!A11="","",종목!A11) | B41: =IF(종목!A11="","",종목!B11) | C41: =IF(종목!A11="","",게임설정!$B$9) | K41: =IF(D41="","",D41+E41) | L41: =IF(F41="","",F41+G41) | M41: =IF(K41="","",K41-L41) | N41: =IF(H41="","",H41-I41) | O41: =IF(N41="","",N41-J41) | P41: =IF(OR(M41="",M41<=0),"자본잠식",ROUND(L41/M41*100,1)) | Q41: =IF(OR(M41="",M41<=0),"—",ROUND(O41/M41*100,1))
...

Sheet 힌트
A1: ④ 힌트 (라운드 × 등급)
A2: ★ R2 힌트 = "R2 연도→다음 연도" 변동 예고. R1은 지급 없음(작성 불필요). 방향(up=호재/down=악재/flat=중립)·관련 종목ID(쉼표 구분, 예: S04,S02)는 선택이지만 채우면 자동 검증·종목 링크가 작동해요. 학생에겐 방향이 안 보여요.
A4: 라운드 | B4: 등급(S~D) | C4: 힌트 문구 | D4: 방향(up/down/flat) (선택) | E4: 관련 종목ID (선택)

Sheet 시황
A1: ⑤ 시황 (연도별 거시경제)
A2: 한 행 = 한 해. 실제 역사와 비슷하게 쓰면 교육 효과가 좋아요. 한 줄 요약은 학생 시황판 맨 위에 크게 보여요.
A4: 연도 | B4: 한 줄 요약 | C4: 코스피지수(pt) | D4: S&P 500(pt) | E4: 일본지수(pt) | F4: 유럽지수(pt) | G4: 기준금리(%) | H4: 물가상승률(%) | I4: 국제유가($) | J4: 금($/oz)
A5: =게임설정!$B$9 -> 2020
A6: =게임설정!$B$10 -> 2021
A7: =게임설정!$B$11 -> 2022
A8: =게임설정!$B$12 -> 2023
A9: =게임설정!$B$13 -> 2024
A10: =게임설정!$B$8 -> 2025

Sheet 등락률(자동)
A1: ★ 등락률 (자동 계산 · 참고용 — 힌트 방향 근거)
A2: 종목 시트에 가격을 넣으면 연도별 등락률이 자동 계산돼요. 힌트 방향(호재·악재) 정할 때 근거로 보세요. 이 시트는 자동이라 채우지 않습니다. (가격을 %로 넣은 칸은 —로 표시)
A4: 종목ID | B4: 종목명 | C4: =게임설정!$B$9&"→"&게임설정!$B$10 -> 2020→2021 | D4: =게임설정!$B$10&"→"&게임설정!$B$11 -> 2021→2022 | E4: =게임설정!$B$11&"→"&게임설정!$B$12 -> 2022→2023 | F4: =게임설정!$B$12&"→"&게임설정!$B$13 -> 2023→2024 | G4: =게임설정!$B$13&"→"&게임설정!$B$8 -> 2024→2025
A5: =IF(종목!A5="","",종목!A5) | B5: =IF(종목!B5="","",종목!B5) | C5: =IF(종목!$A5="","",IF(종목!G5="","상장/정지",IF(종목!G5=0,"폐지(-100%)",IF(OR(종목!F5="",종목!F5=0),"신규상장",IFERROR(TEXT(종목!G5/종목!F5-1,"+0%;-0%"),"—"))))) | D5: =IF(종목!$A5="","",IF(종목!H5="","상장/정지",IF(종목!H5=0,"폐지(-100%)",IF(OR(종목!G5="",종목!G5=0),"신규상장",IFERROR(TEXT(종목!H5/종목!G5-1,"+0%;-0%"),"—"))))) | E5: =IF(종목!$A5="","",IF(종목!I5="","상장/정지",IF(종목!I5=0,"폐지(-100%)",IF(OR(종목!H5="",종목!H5=0),"신규상장",IFERROR(TEXT(종목!I5/종목!H5-1,"+0%;-0%"),"—"))))) | F5: =IF(종목!$A5="","",IF(종목!J5="","상장/정지",IF(종목!J5=0,"폐지(-100%)",IF(OR(종목!I5="",종목!I5=0),"신규상장",IFERROR(TEXT(종목!J5/종목!I5-1,"+0%;-0%"),"—"))))) | G5: =IF(종목!$A5="","",IF(종목!K5="","상장/정지",IF(종목!K5=0,"폐지(-100%)",IF(OR(종목!J5="",종목!J5=0),"신규상장",IFERROR(TEXT(종목!K5/종목!J5-1,"+0%;-0%"),"—")))))
A6: =IF(종목!A6="","",종목!A6) | B6: =IF(종목!B6="","",종목!B6) | C6: =IF(종목!$A6="","",IF(종목!G6="","상장/정지",IF(종목!G6=0,"폐지(-100%)",IF(OR(종목!F6="",종목!F6=0),"신규상장",IFERROR(TEXT(종목!G6/종목!F6-1,"+0%;-0%"),"—"))))) | D6: =IF(종목!$A6="","",IF(종목!H6="","상장/정지",IF(종목!H6=0,"폐지(-100%)",IF(OR(종목!G6="",종목!G6=0),"신규상장",IFERROR(TEXT(종목!H6/종목!G6-1,"+0%;-0%"),"—"))))) | E6: =IF(종목!$A6="","",IF(종목!I6="","상장/정지",IF(종목!I6=0,"폐지(-100%)",IF(OR(종목!H6="",종목!H6=0),"신규상장",IFERROR(TEXT(종목!I6/종목!H6-1,"+0%;-0%"),"—"))))) | F6: =IF(종목!$A6="","",IF(종목!J6="","상장/정지",IF(종목!J6=0,"폐지(-100%)",IF(OR(종목!I6="",종목!I6=0),"신규상장",IFERROR(TEXT(종목!J6/종목!I6-1,"+0%;-0%"),"—"))))) | G6: =IF(종목!$A6="","",IF(종목!K6="","상장/정지",IF(종목!K6=0,"폐지(-100%)",IF(OR(종목!J6="",종목!J6=0),"신규상장",IFERROR(TEXT(종목!K6/종목!J6-1,"+0%;-0%"),"—")))))
A7: =IF(종목!A7="","",종목!A7) | B7: =IF(종목!B7="","",종목!B7) | C7: =IF(종목!$A7="","",IF(종목!G7="","상장/정지",IF(종목!G7=0,"폐지(-100%)",IF(OR(종목!F7="",종목!F7=0),"신규상장",IFERROR(TEXT(종목!G7/종목!F7-1,"+0%;-0%"),"—"))))) | D7: =IF(종목!$A7="","",IF(종목!H7="","상장/정지",IF(종목!H7=0,"폐지(-100%)",IF(OR(종목!G7="",종목!G7=0),"신규상장",IFERROR(TEXT(종목!H7/종목!G7-1,"+0%;-0%"),"—"))))) | E7: =IF(종목!$A7="","",IF(종목!I7="","상장/정지",IF(종목!I7=0,"폐지(-100%)",IF(OR(종목!H7="",종목!H7=0),"신규상장",IFERROR(TEXT(종목!I7/종목!H7-1,"+0%;-0%"),"—"))))) | F7: =IF(종목!$A7="","",IF(종목!J7="","상장/정지",IF(종목!J7=0,"폐지(-100%)",IF(OR(종목!I7="",종목!I7=0),"신규상장",IFERROR(TEXT(종목!J7/종목!I7-1,"+0%;-0%"),"—"))))) | G7: =IF(종목!$A7="","",IF(종목!K7="","상장/정지",IF(종목!K7=0,"폐지(-100%)",IF(OR(종목!J7="",종목!J7=0),"신규상장",IFERROR(TEXT(종목!K7/종목!J7-1,"+0%;-0%"),"—")))))
A8: =IF(종목!A8="","",종목!A8) | B8: =IF(종목!B8="","",종목!B8) | C8: =IF(종목!$A8="","",IF(종목!G8="","상장/정지",IF(종목!G8=0,"폐지(-100%)",IF(OR(종목!F8="",종목!F8=0),"신규상장",IFERROR(TEXT(종목!G8/종목!F8-1,"+0%;-0%"),"—"))))) | D8: =IF(종목!$A8="","",IF(종목!H8="","상장/정지",IF(종목!H8=0,"폐지(-100%)",IF(OR(종목!G8="",종목!G8=0),"신규상장",IFERROR(TEXT(종목!H8/종목!G8-1,"+0%;-0%"),"—"))))) | E8: =IF(종목!$A8="","",IF(종목!I8="","상장/정지",IF(종목!I8=0,"폐지(-100%)",IF(OR(종목!H8="",종목!H8=0),"신규상장",IFERROR(TEXT(종목!I8/종목!H8-1,"+0%;-0%"),"—"))))) | F8: =IF(종목!$A8="","",IF(종목!J8="","상장/정지",IF(종목!J8=0,"폐지(-100%)",IF(OR(종목!I8="",종목!I8=0),"신규상장",IFERROR(TEXT(종목!J8/종목!I8-1,"+0%;-0%"),"—"))))) | G8: =IF(종목!$A8="","",IF(종목!K8="","상장/정지",IF(종목!K8=0,"폐지(-100%)",IF(OR(종목!J8="",종목!J8=0),"신규상장",IFERROR(TEXT(종목!K8/종목!J8-1,"+0%;-0%"),"—")))))
A9: =IF(종목!A9="","",종목!A9) | B9: =IF(종목!B9="","",종목!B9) | C9: =IF(종목!$A9="","",IF(종목!G9="","상장/정지",IF(종목!G9=0,"폐지(-100%)",IF(OR(종목!F9="",종목!F9=0),"신규상장",IFERROR(TEXT(종목!G9/종목!F9-1,"+0%;-0%"),"—"))))) | D9: =IF(종목!$A9="","",IF(종목!H9="","상장/정지",IF(종목!H9=0,"폐지(-100%)",IF(OR(종목!G9="",종목!G9=0),"신규상장",IFERROR(TEXT(종목!H9/종목!G9-1,"+0%;-0%"),"—"))))) | E9: =IF(종목!$A9="","",IF(종목!I9="","상장/정지",IF(종목!I9=0,"폐지(-100%)",IF(OR(종목!H9="",종목!H9=0),"신규상장",IFERROR(TEXT(종목!I9/종목!H9-1,"+0%;-0%"),"—"))))) | F9: =IF(종목!$A9="","",IF(종목!J9="","상장/정지",IF(종목!J9=0,"폐지(-100%)",IF(OR(종목!I9="",종목!I9=0),"신규상장",IFERROR(TEXT(종목!J9/종목!I9-1,"+0%;-0%"),"—"))))) | G9: =IF(종목!$A9="","",IF(종목!K9="","상장/정지",IF(종목!K9=0,"폐지(-100%)",IF(OR(종목!J9="",종목!J9=0),"신규상장",IFERROR(TEXT(종목!K9/종목!J9-1,"+0%;-0%"),"—")))))
A10: =IF(종목!A10="","",종목!A10) | B10: =IF(종목!B10="","",종목!B10) | C10: =IF(종목!$A10="","",IF(종목!G10="","상장/정지",IF(종목!G10=0,"폐지(-100%)",IF(OR(종목!F10="",종목!F10=0),"신규상장",IFERROR(TEXT(종목!G10/종목!F10-1,"+0%;-0%"),"—"))))) | D10: =IF(종목!$A10="","",IF(종목!H10="","상장/정지",IF(종목!H10=0,"폐지(-100%)",IF(OR(종목!G10="",종목!G10=0),"신규상장",IFERROR(TEXT(종목!H10/종목!G10-1,"+0%;-0%"),"—"))))) | E10: =IF(종목!$A10="","",IF(종목!I10="","상장/정지",IF(종목!I10=0,"폐지(-100%)",IF(OR(종목!H10="",종목!H10=0),"신규상장",IFERROR(TEXT(종목!I10/종목!H10-1,"+0%;-0%"),"—"))))) | F10: =IF(종목!$A10="","",IF(종목!J10="","상장/정지",IF(종목!J10=0,"폐지(-100%)",IF(OR(종목!I10="",종목!I10=0),"신규상장",IFERROR(TEXT(종목!J10/종목!I10-1,"+0%;-0%"),"—"))))) | G10: =IF(종목!$A10="","",IF(종목!K10="","상장/정지",IF(종목!K10=0,"폐지(-100%)",IF(OR(종목!J10="",종목!J10=0),"신규상장",IFERROR(TEXT(종목!K10/종목!J10-1,"+0%;-0%"),"—")))))
A11: =IF(종목!A11="","",종목!A11) | B11: =IF(종목!B11="","",종목!B11) | C11: =IF(종목!$A11="","",IF(종목!G11="","상장/정지",IF(종목!G11=0,"폐지(-100%)",IF(OR(종목!F11="",종목!F11=0),"신규상장",IFERROR(TEXT(종목!G11/종목!F11-1,"+0%;-0%"),"—"))))) | D11: =IF(종목!$A11="","",IF(종목!H11="","상장/정지",IF(종목!H11=0,"폐지(-100%)",IF(OR(종목!G11="",종목!G11=0),"신규상장",IFERROR(TEXT(종목!H11/종목!G11-1,"+0%;-0%"),"—"))))) | E11: =IF(종목!$A11="","",IF(종목!I11="","상장/정지",IF(종목!I11=0,"폐지(-100%)",IF(OR(종목!H11="",종목!H11=0),"신규상장",IFERROR(TEXT(종목!I11/종목!H11-1,"+0%;-0%"),"—"))))) | F11: =IF(종목!$A11="","",IF(종목!J11="","상장/정지",IF(종목!J11=0,"폐지(-100%)",IF(OR(종목!I11="",종목!I11=0),"신규상장",IFERROR(TEXT(종목!J11/종목!I11-1,"+0%;-0%"),"—"))))) | G11: =IF(종목!$A11="","",IF(종목!K11="","상장/정지",IF(종목!K11=0,"폐지(-100%)",IF(OR(종목!J11="",종목!J11=0),"신규상장",IFERROR(TEXT(종목!K11/종목!J11-1,"+0%;-0%"),"—")))))
A12: =IF(종목!A12="","",종목!A12) | B12: =IF(종목!B12="","",종목!B12) | C12: =IF(종목!$A12="","",IF(종목!G12="","상장/정지",IF(종목!G12=0,"폐지(-100%)",IF(OR(종목!F12="",종목!F12=0),"신규상장",IFERROR(TEXT(종목!G12/종목!F12-1,"+0%;-0%"),"—"))))) | D12: =IF(종목!$A12="","",IF(종목!H12="","상장/정지",IF(종목!H12=0,"폐지(-100%)",IF(OR(종목!G12="",종목!G12=0),"신규상장",IFERROR(TEXT(종목!H12/종목!G12-1,"+0%;-0%"),"—"))))) | E12: =IF(종목!$A12="","",IF(종목!I12="","상장/정지",IF(종목!I12=0,"폐지(-100%)",IF(OR(종목!H12="",종목!H12=0),"신규상장",IFERROR(TEXT(종목!I12/종목!H12-1,"+0%;-0%"),"—"))))) | F12: =IF(종목!$A12="","",IF(종목!J12="","상장/정지",IF(종목!J12=0,"폐지(-100%)",IF(OR(종목!I12="",종목!I12=0),"신규상장",IFERROR(TEXT(종목!J12/종목!I12-1,"+0%;-0%"),"—"))))) | G12: =IF(종목!$A12="","",IF(종목!K12="","상장/정지",IF(종목!K12=0,"폐지(-100%)",IF(OR(종목!J12="",종목!J12=0),"신규상장",IFERROR(TEXT(종목!K12/종목!J12-1,"+0%;-0%"),"—")))))
A13: =IF(종목!A13="","",종목!A13) | B13: =IF(종목!B13="","",종목!B13) | C13: =IF(종목!$A13="","",IF(종목!G13="","상장/정지",IF(종목!G13=0,"폐지(-100%)",IF(OR(종목!F13="",종목!F13=0),"신규상장",IFERROR(TEXT(종목!G13/종목!F13-1,"+0%;-0%"),"—"))))) | D13: =IF(종목!$A13="","",IF(종목!H13="","상장/정지",IF(종목!H13=0,"폐지(-100%)",IF(OR(종목!G13="",종목!G13=0),"신규상장",IFERROR(TEXT(종목!H13/종목!G13-1,"+0%;-0%"),"—"))))) | E13: =IF(종목!$A13="","",IF(종목!I13="","상장/정지",IF(종목!I13=0,"폐지(-100%)",IF(OR(종목!H13="",종목!H13=0),"신규상장",IFERROR(TEXT(종목!I13/종목!H13-1,"+0%;-0%"),"—"))))) | F13: =IF(종목!$A13="","",IF(종목!J13="","상장/정지",IF(종목!J13=0,"폐지(-100%)",IF(OR(종목!I13="",종목!I13=0),"신규상장",IFERROR(TEXT(종목!J13/종목!I13-1,"+0%;-0%"),"—"))))) | G13: =IF(종목!$A13="","",IF(종목!K13="","상장/정지",IF(종목!K13=0,"폐지(-100%)",IF(OR(종목!J13="",종목!J13=0),"신규상장",IFERROR(TEXT(종목!K13/종목!J13-1,"+0%;-0%"),"—")))))
A14: =IF(종목!A14="","",종목!A14) | B14: =IF(종목!B14="","",종목!B14) | C14: =IF(종목!$A14="","",IF(종목!G14="","상장/정지",IF(종목!G14=0,"폐지(-100%)",IF(OR(종목!F14="",종목!F14=0),"신규상장",IFERROR(TEXT(종목!G14/종목!F14-1,"+0%;-0%"),"—"))))) | D14: =IF(종목!$A14="","",IF(종목!H14="","상장/정지",IF(종목!H14=0,"폐지(-100%)",IF(OR(종목!G14="",종목!G14=0),"신규상장",IFERROR(TEXT(종목!H14/종목!G14-1,"+0%;-0%"),"—"))))) | E14: =IF(종목!$A14="","",IF(종목!I14="","상장/정지",IF(종목!I14=0,"폐지(-100%)",IF(OR(종목!H14="",종목!H14=0),"신규상장",IFERROR(TEXT(종목!I14/종목!H14-1,"+0%;-0%"),"—"))))) | F14: =IF(종목!$A14="","",IF(종목!J14="","상장/정지",IF(종목!J14=0,"폐지(-100%)",IF(OR(종목!I14="",종목!I14=0),"신규상장",IFERROR(TEXT(종목!J14/종목!I14-1,"+0%;-0%"),"—"))))) | G14: =IF(종목!$A14="","",IF(종목!K14="","상장/정지",IF(종목!K14=0,"폐지(-100%)",IF(OR(종목!J14="",종목!J14=0),"신규상장",IFERROR(TEXT(종목!K14/종목!J14-1,"+0%;-0%"),"—")))))
A15: =IF(종목!A15="","",종목!A15) | B15: =IF(종목!B15="","",종목!B15) | C15: =IF(종목!$A15="","",IF(종목!G15="","상장/정지",IF(종목!G15=0,"폐지(-100%)",IF(OR(종목!F15="",종목!F15=0),"신규상장",IFERROR(TEXT(종목!G15/종목!F15-1,"+0%;-0%"),"—"))))) | D15: =IF(종목!$A15="","",IF(종목!H15="","상장/정지",IF(종목!H15=0,"폐지(-100%)",IF(OR(종목!G15="",종목!G15=0),"신규상장",IFERROR(TEXT(종목!H15/종목!G15-1,"+0%;-0%"),"—"))))) | E15: =IF(종목!$A15="","",IF(종목!I15="","상장/정지",IF(종목!I15=0,"폐지(-100%)",IF(OR(종목!H15="",종목!H15=0),"신규상장",IFERROR(TEXT(종목!I15/종목!H15-1,"+0%;-0%"),"—"))))) | F15: =IF(종목!$A15="","",IF(종목!J15="","상장/정지",IF(종목!J15=0,"폐지(-100%)",IF(OR(종목!I15="",종목!I15=0),"신규상장",IFERROR(TEXT(종목!J15/종목!I15-1,"+0%;-0%"),"—"))))) | G15: =IF(종목!$A15="","",IF(종목!K15="","상장/정지",IF(종목!K15=0,"폐지(-100%)",IF(OR(종목!J15="",종목!J15=0),"신규상장",IFERROR(TEXT(종목!K15/종목!J15-1,"+0%;-0%"),"—")))))
A16: =IF(종목!A16="","",종목!A16) | B16: =IF(종목!B16="","",종목!B16) | C16: =IF(종목!$A16="","",IF(종목!G16="","상장/정지",IF(종목!G16=0,"폐지(-100%)",IF(OR(종목!F16="",종목!F16=0),"신규상장",IFERROR(TEXT(종목!G16/종목!F16-1,"+0%;-0%"),"—"))))) | D16: =IF(종목!$A16="","",IF(종목!H16="","상장/정지",IF(종목!H16=0,"폐지(-100%)",IF(OR(종목!G16="",종목!G16=0),"신규상장",IFERROR(TEXT(종목!H16/종목!G16-1,"+0%;-0%"),"—"))))) | E16: =IF(종목!$A16="","",IF(종목!I16="","상장/정지",IF(종목!I16=0,"폐지(-100%)",IF(OR(종목!H16="",종목!H16=0),"신규상장",IFERROR(TEXT(종목!I16/종목!H16-1,"+0%;-0%"),"—"))))) | F16: =IF(종목!$A16="","",IF(종목!J16="","상장/정지",IF(종목!J16=0,"폐지(-100%)",IF(OR(종목!I16="",종목!I16=0),"신규상장",IFERROR(TEXT(종목!J16/종목!I16-1,"+0%;-0%"),"—"))))) | G16: =IF(종목!$A16="","",IF(종목!K16="","상장/정지",IF(종목!K16=0,"폐지(-100%)",IF(OR(종목!J16="",종목!J16=0),"신규상장",IFERROR(TEXT(종목!K16/종목!J16-1,"+0%;-0%"),"—")))))
... A50: =IF(종목!A50="","",종목!A50) | B50: =IF(종목!B50="","",종목!B50) | C50: =IF(종목!$A50="","",IF(종목!G50="","상장/정지",IF(종목!G50=0,"폐지(-100%)",IF(OR(종목!F50="",종목!F50=0),"신규상장",IFERROR(TEXT(종목!G50/종목!F50-1,"+0%;-0%"),"—"))))) | D50: =IF(종목!$A50="","",IF(종목!H50="","상장/정지",IF(종목!H50=0,"폐지(-100%)",IF(OR(종목!G50="",종목!G50=0),"신규상장",IFERROR(TEXT(종목!H50/종목!G50-1,"+0%;-0%"),"—"))))) | E50: =IF(종목!$A50="","",IF(종목!I50="","상장/정지",IF(종목!I50=0,"폐지(-100%)",IF(OR(종목!H50="",종목!H50=0),"신규상장",IFERROR(TEXT(종목!I50/종목!H50-1,"+0%;-0%"),"—"))))) | F50: =IF(종목!$A50="","",IF(종목!J50="","상장/정지",IF(종목!J50=0,"폐지(-100%)",IF(OR(종목!I50="",종목!I50=0),"신규상장",IFERROR(TEXT(종목!J50/종목!I50-1,"+0%;-0%"),"—"))))) | G50: =IF(종목!$A50="","",IF(종목!K50="","상장/정지",IF(종목!K50=0,"폐지(-100%)",IF(OR(종목!J50="",종목!J50=0),"신규상장",IFERROR(TEXT(종목!K50/종목!J50-1,"+0%;-0%"),"—")))))
